Workbook

Sheet Sheet 1
B3: 1 | C3: 2 | D3: 3 | E3: 4 | F3: 5 | G3: 6 | H3: 7 | I3: 8 | J3: 9 | K3: 10 | L3: 11 | M3: 12
A4: A | B4: 0.061 | C4: 0.064 | D4: 0.067 | E4: 0.072 | F4: 0.075 | G4: 0.076 | H4: 0.079 | I4: 0.08 | J4: 0.082 | K4: 0.083 | L4: 0.085 | M4: 0.087 | N4: 275
A5: B | B5: 0.075 | C5: 0.075 | D5: 0.072 | E5: 0.07 | F5: 0.076 | G5: 0.079 | H5: 0.08 | I5: 0.084 | J5: 0.085 | K5: 0.086 | L5: 0.089 | M5: 0.091 | N5: 275
A6: C | B6: 0.061 | C6: 0.061 | D6: 0.066 | E6: 0.069 | F6: 0.072 | G6: 0.074 | H6: 0.076 | I6: 0.078 | J6: 0.076 | K6: 0.082 | L6: 0.082 | M6: 0.083 | N6: 275
A7: D | B7: 0.061 | C7: 0.061 | D7: 0.064 | E7: 0.065 | F7: 0.067 | G7: 0.069 | H7: 0.072 | I7: 0.072 | J7: 0.073 | K7: 0.075 | L7: 0.102 | M7: 0.081 | N7: 275
A8: E | B8: 0.09 | C8: 0.094 | D8: 0.109 | E8: 0.095 | F8: 0.096 | G8: 0.099 | H8: 0.098 | I8: 0.102 | J8: 0.112 | K8: 0.104 | L8: 0.107 | M8: 0.108 | N8: 275
A9: F | B9: 0.097 | C9: 0.089 | D9: 0.098 | E9: 0.099 | F9: 0.1 | G9: 0.1 | H9: 0.103 | I9: 0.107 | J9: 0.111 | K9: 0.109 | L9: 0.11 | M9: 0.112 | N9: 275
A10: G | B10: 0.087 | C10: 0.089 | D10: 0.092 | E10: 0.092 | F10: 0.094 | G10: 0.096 | H10: 0.098 | I10: 0.1 | J10: 0.101 | K10: 0.106 | L10: 0.107 | M10: 0.108 | N10: 275
A11: H | B11: 0.08 | C11: 0.084 | D11: 0.082 | E11: 0.082 | F11: 0.085 | G11: 0.086 | H11: 0.087 | I11: 0.089 | J11: 0.09 | K11: 0.092 | L11: 0.093 | M11: 0.094 | N11: 275
B18: =1.5*60 -> 90

Sheet Info
B3: 1 | C3: 2 | D3: 3 | E3: 4 | F3: 5 | G3: 6 | H3: 7 | I3: 8 | J3: 9 | K3: 10 | L3: 11 | M3: 12
A4: A | B4: ='Sheet 1'!B4 -> 0.061 | C4: ='Sheet 1'!C4 -> 0.064 | D4: ='Sheet 1'!D4 -> 0.067 | E4: ='Sheet 1'!E4 -> 0.072 | F4: ='Sheet 1'!F4 -> 0.075 | G4: ='Sheet 1'!G4 -> 0.076 | H4: ='Sheet 1'!H4 -> 0.079 | I4: ='Sheet 1'!I4 -> 0.08 | ... M4: ='Sheet 1'!M4 -> 0.087 | N4: 275
A5: B | B5: ='Sheet 1'!B5 -> 0.075 | C5: ='Sheet 1'!C5 -> 0.075 | D5: ='Sheet 1'!D5 -> 0.072 | E5: ='Sheet 1'!E5 -> 0.07 | F5: ='Sheet 1'!F5 -> 0.076 | G5: ='Sheet 1'!G5 -> 0.079 | H5: ='Sheet 1'!H5 -> 0.08 | I5: ='Sheet 1'!I5 -> 0.084 | ... M5: ='Sheet 1'!M5 -> 0.091 | N5: 275
A6: C | B6: ='Sheet 1'!B6 -> 0.061 | C6: ='Sheet 1'!C6 -> 0.061 | D6: ='Sheet 1'!D6 -> 0.066 | E6: ='Sheet 1'!E6 -> 0.069 | F6: ='Sheet 1'!F6 -> 0.072 | G6: ='Sheet 1'!G6 -> 0.074 | H6: ='Sheet 1'!H6 -> 0.076 | I6: ='Sheet 1'!I6 -> 0.078 | ... M6: ='Sheet 1'!M6 -> 0.083 | N6: 275
A7: D | B7: ='Sheet 1'!B7 -> 0.061 | C7: ='Sheet 1'!C7 -> 0.061 | D7: ='Sheet 1'!D7 -> 0.064 | E7: ='Sheet 1'!E7 -> 0.065 | F7: ='Sheet 1'!F7 -> 0.067 | G7: ='Sheet 1'!G7 -> 0.069 | H7: ='Sheet 1'!H7 -> 0.072 | I7: ='Sheet 1'!I7 -> 0.072 | ... M7: ='Sheet 1'!M7 -> 0.081 | N7: 275
A8: E | B8: ='Sheet 1'!B8 -> 0.09 | C8: ='Sheet 1'!C8 -> 0.094 | D8: ='Sheet 1'!D8 -> 0.109 | E8: ='Sheet 1'!E8 -> 0.095 | F8: ='Sheet 1'!F8 -> 0.096 | G8: ='Sheet 1'!G8 -> 0.099 | H8: ='Sheet 1'!H8 -> 0.098 | I8: ='Sheet 1'!I8 -> 0.102 | ... M8: ='Sheet 1'!M8 -> 0.108 | N8: 275
A9: F | B9: ='Sheet 1'!B9 -> 0.097 | C9: ='Sheet 1'!C9 -> 0.089 | D9: ='Sheet 1'!D9 -> 0.098 | E9: ='Sheet 1'!E9 -> 0.099 | F9: ='Sheet 1'!F9 -> 0.1 | G9: ='Sheet 1'!G9 -> 0.1 | H9: ='Sheet 1'!H9 -> 0.103 | I9: ='Sheet 1'!I9 -> 0.107 | ... M9: ='Sheet 1'!M9 -> 0.112 | N9: 275
A10: G | B10: ='Sheet 1'!B10 -> 0.087 | C10: ='Sheet 1'!C10 -> 0.089 | D10: ='Sheet 1'!D10 -> 0.092 | E10: ='Sheet 1'!E10 -> 0.092 | F10: ='Sheet 1'!F10 -> 0.094 | G10: ='Sheet 1'!G10 -> 0.096 | H10: ='Sheet 1'!H10 -> 0.098 | I10: ='Sheet 1'!I10 -> 0.1 | ... M10: ='Sheet 1'!M10 -> 0.108 | N10: 275
A11: H | B11: ='Sheet 1'!B11 -> 0.08 | C11: ='Sheet 1'!C11 -> 0.084 | D11: ='Sheet 1'!D11 -> 0.082 | E11: ='Sheet 1'!E11 -> 0.082 | F11: ='Sheet 1'!F11 -> 0.085 | G11: ='Sheet 1'!G11 -> 0.086 | H11: ='Sheet 1'!H11 -> 0.087 | I11: ='Sheet 1'!I11 -> 0.089 | ... M11: ='Sheet 1'!M11 -> 0.094 | N11: 275
A16: Time (min) | B16: 17 | C16: =B16+17 -> 34 | D16: =C16+17 -> 51 | E16: =D16+17 -> 68 | F16: =E16+17 -> 85 | G16: =F16+17 -> 102 | H16: =G16+17 -> 119 | I16: =H16+17 -> 136 | J16: =I16+17 -> 153 | ... M16: =L16+17 -> 204
A17: Ch1 (A) | B17: =B4 -> 0.061 | C17: =C4 -> 0.064 | D17: =D4 -> 0.067 | E17: =E4 -> 0.072 | F17: =F4 -> 0.075 | G17: =G4 -> 0.076 | H17: =H4 -> 0.079 | I17: =I4 -> 0.08 | ... M17: =M4 -> 0.087
A18: Ch2 (B) | B18: =B5 -> 0.075 | C18: =C5 -> 0.075 | D18: =D5 -> 0.072 | E18: =E5 -> 0.07 | F18: =F5 -> 0.076 | G18: =G5 -> 0.079 | H18: =H5 -> 0.08 | I18: =I5 -> 0.084 | ... M18: =M5 -> 0.091
A19: Ch3 (C) | B19: =B6 -> 0.061 | C19: =C6 -> 0.061 | D19: =D6 -> 0.066 | E19: =E6 -> 0.069 | F19: =F6 -> 0.072 | G19: =G6 -> 0.074 | H19: =H6 -> 0.076 | I19: =I6 -> 0.078 | ... M19: =M6 -> 0.083
A20: Ch4 (D) | B20: =B7 -> 0.061 | C20: =C7 -> 0.061 | D20: =D7 -> 0.064 | E20: =E7 -> 0.065 | F20: =F7 -> 0.067 | G20: =G7 -> 0.069 | H20: =H7 -> 0.072 | I20: =I7 -> 0.072 | ... K20: =K7 -> 0.075 | M20: =M7 -> 0.081 | P20: 0.102
A22: Time (min) | B22: =M16+17 -> 221 | C22: =B22+17 -> 238 | D22: =C22+17 -> 255 | E22: =D22+17 -> 272 | F22: =E22+17 -> 289 | G22: =F22+17 -> 306 | H22: =G22+17 -> 323 | I22: =H22+17 -> 340 | J22: =I22+17 -> 357 | ... M22: =L22+17 -> 408
A23: Ch1 (E) | B23: =B8 -> 0.09 | C23: =C8 -> 0.094 | D23: =D8 -> 0.109 | E23: =E8 -> 0.095 | F23: =F8 -> 0.096 | G23: =G8 -> 0.099 | H23: =H8 -> 0.098 | I23: =I8 -> 0.102 | ... M23: =M8 -> 0.108
A24: Ch2 (F) | B24: =B9 -> 0.097 | C24: =C9 -> 0.089 | D24: =D9 -> 0.098 | E24: =E9 -> 0.099 | F24: =F9 -> 0.1 | G24: =G9 -> 0.1 | H24: =H9 -> 0.103 | I24: =I9 -> 0.107 | ... M24: =M9 -> 0.112
A25: Ch3 (G) | B25: =B10 -> 0.087 | C25: =C10 -> 0.089 | D25: =D10 -> 0.092 | E25: =E10 -> 0.092 | F25: =F10 -> 0.094 | G25: =G10 -> 0.096 | H25: =H10 -> 0.098 | I25: =I10 -> 0.1 | ... M25: =M10 -> 0.108
A26: Ch4 (H) | B26: =B11 -> 0.08 | C26: =C11 -> 0.084 | D26: =D11 -> 0.082 | E26: =E11 -> 0.082 | F26: =F11 -> 0.085 | G26: =G11 -> 0.086 | H26: =H11 -> 0.087 | I26: =I11 -> 0.089 | ... M26: =M11 -> 0.094
A29: Formulations
A30: Ch1 | B30: P23-DCF-1
A31: Ch2 | B31: P23-DCF-2
A32: Ch3 | B32: P23-DCF-3 | N32: =5*60 -> 300
A33: Ch4 | B33: P23-DCF-4
A36: Receptor cell (ml)
A37: Ch1 | B37: 19.3
A38: Ch2 | B38: 19.7
A39: Ch3 | B39: 19.5
A40: Ch4 | B40: 24.1
A43: Donor cell (ml)
A44: Ch1 | B44: 0.5 | C44: 250 | D44: ug DCF
A45: Ch2 | B45: 0.5 | C45: 250 | D45: ug DCF
A46: Ch3 | B46: 0.5 | C46: 250 | D46: ug DCF
A47: Ch4 | B47: 0.5 | C47: 250 | D47: ug DCF
A50: Flow RMSP (Q+) / (Q-) ml/min | C50: 30 RPM
A51: Ch1
A52: Ch2
A53: Ch3
A54: Ch4
A57: Temperature (oC) +/-1
...

Sheet Correction Blank
A3: Correction O.D
B4: Time (min) | C4: =17 -> 17 | D4: =C4+17 -> 34 | E4: =D4+17 -> 51 | F4: =E4+17 -> 68 | G4: =F4+17 -> 85 | H4: =G4+17 -> 102 | I4: =H4+17 -> 119 | J4: =I4+17 -> 136 | K4: =J4+17 -> 153 | ... Z4: =Y4+17 -> 408
B5: P23-DCF-1 | C5: =Info!B17-0.05 -> 0.011 | D5: =Info!C17-0.05 -> 0.014 | E5: =Info!D17-0.05 -> 0.017 | F5: =Info!E17-0.05 -> 0.022 | G5: =Info!F17-0.05 -> 0.025 | H5: =Info!G17-0.05 -> 0.026 | I5: =Info!H17-0.05 -> 0.029 | J5: =Info!I17-0.05 -> 0.03 | ... N5: =Info!M17-0.05 -> 0.037 | O5: =Info!B23-0.05 -> 0.04 | P5: =Info!C23-0.05 -> 0.044 | Q5: =Info!D23-0.05 -> 0.059 | R5: =Info!E23-0.05 -> 0.045 | S5: =Info!F23-0.05 -> 0.046 | T5: =Info!G23-0.05 -> 0.049 | U5: =Info!H23-0.05 -> 0.048 | V5: =Info!I23-0.05 -> 0.052 | ... Z5: =Info!M23-0.05 -> 0.058
B6: P23-DCF-2 | C6: =Info!B18-0.05 -> 0.025 | D6: =Info!C18-0.05 -> 0.025 | E6: =Info!D18-0.05 -> 0.022 | F6: =Info!E18-0.05 -> 0.02 | G6: =Info!F18-0.05 -> 0.026 | H6: =Info!G18-0.05 -> 0.029 | I6: =Info!H18-0.05 -> 0.03 | J6: =Info!I18-0.05 -> 0.034 | ... N6: =Info!M18-0.05 -> 0.041 | O6: =Info!B24-0.05 -> 0.047 | P6: =Info!C24-0.05 -> 0.039 | Q6: =Info!D24-0.05 -> 0.048 | R6: =Info!E24-0.05 -> 0.049 | S6: =Info!F24-0.05 -> 0.05 | T6: =Info!G24-0.05 -> 0.05 | U6: =Info!H24-0.05 -> 0.053 | V6: =Info!I24-0.05 -> 0.057 | ... Z6: =Info!M24-0.05 -> 0.062
B7: P23-DCF-3 | C7: =Info!B19-0.05 -> 0.011 | D7: =Info!C19-0.05 -> 0.011 | E7: =Info!D19-0.05 -> 0.016 | F7: =Info!E19-0.05 -> 0.019 | G7: =Info!F19-0.05 -> 0.022 | H7: =Info!G19-0.05 -> 0.024 | I7: =Info!H19-0.05 -> 0.026 | J7: =Info!I19-0.05 -> 0.028 | ... N7: =Info!M19-0.05 -> 0.033 | O7: =Info!B25-0.05 -> 0.037 | P7: =Info!C25-0.05 -> 0.039 | Q7: =Info!D25-0.05 -> 0.042 | R7: =Info!E25-0.05 -> 0.042 | S7: =Info!F25-0.05 -> 0.044 | T7: =Info!G25-0.05 -> 0.046 | U7: =Info!H25-0.05 -> 0.048 | V7: =Info!I25-0.05 -> 0.05 | ... Z7: =Info!M25-0.05 -> 0.058
B8: P23-DCF-4 | C8: =Info!B20-0.05 -> 0.011 | D8: =Info!C20-0.05 -> 0.011 | E8: =Info!D20-0.05 -> 0.014 | F8: =Info!E20-0.05 -> 0.015 | G8: =Info!F20-0.05 -> 0.017 | H8: =Info!G20-0.05 -> 0.019 | I8: =Info!H20-0.05 -> 0.022 | J8: =Info!I20-0.05 -> 0.022 | ... L8: =Info!K20-0.05 -> 0.025 | N8: =Info!M20-0.05 -> 0.031 | O8: =Info!B26-0.05 -> 0.03 | P8: =Info!C26-0.05 -> 0.034 | Q8: =Info!D26-0.05 -> 0.032 | R8: =Info!E26-0.05 -> 0.032 | S8: =Info!F26-0.05 -> 0.035 | T8: =Info!G26-0.05 -> 0.036 | U8: =Info!H26-0.05 -> 0.037 | V8: =Info!I26-0.05 -> 0.039 | ... Z8: =Info!M26-0.05 -> 0.044

Sheet Conversions
C2: =0.25/20*100 -> 1.25
A3: Convert to CAF content (ug)
B4: Time (min) | C4: =17 -> 17 | D4: =C4+17 -> 34 | E4: =D4+17 -> 51 | F4: =E4+17 -> 68 | G4: =F4+17 -> 85 | H4: =G4+17 -> 102 | I4: =H4+17 -> 119 | J4: =I4+17 -> 136 | K4: =J4+17 -> 153 | ... Z4: =Y4+17 -> 408
B5: P23-DCF-1 | C5: =('Correction Blank'!C5-$B$19)/$B$18 -> 0.52325581 | D5: =('Correction Blank'!D5-$B$19)/$B$18 -> 0.69767442 | E5: =('Correction Blank'!E5-$B$19)/$B$18 -> 0.87209302 | F5: =('Correction Blank'!F5-$B$19)/$B$18 -> 1.1627907 | G5: =('Correction Blank'!G5-$B$19)/$B$18 -> 1.3372093 | H5: =('Correction Blank'!H5-$B$19)/$B$18 -> 1.3953488 | I5: =('Correction Blank'!I5-$B$19)/$B$18 -> 1.5697674 | J5: =('Correction Blank'!J5-$B$19)/$B$18 -> 1.627907 | ... Z5: =('Correction Blank'!Z5-$B$19)/$B$18 -> 3.255814
B6: P23-DCF-2 | C6: =('Correction Blank'!C6-$B$19)/$B$18 -> 1.3372093 | D6: =('Correction Blank'!D6-$B$19)/$B$18 -> 1.3372093 | E6: =('Correction Blank'!E6-$B$19)/$B$18 -> 1.1627907 | F6: =('Correction Blank'!F6-$B$19)/$B$18 -> 1.0465116 | G6: =('Correction Blank'!G6-$B$19)/$B$18 -> 1.3953488 | H6: =('Correction Blank'!H6-$B$19)/$B$18 -> 1.5697674 | I6: =('Correction Blank'!I6-$B$19)/$B$18 -> 1.627907 | J6: =('Correction Blank'!J6-$B$19)/$B$18 -> 1.8604651 | ... Z6: =('Correction Blank'!Z6-$B$19)/$B$18 -> 3.4883721
B7: P23-DCF-3 | C7: =('Correction Blank'!C7-$B$19)/$B$18 -> 0.52325581 | D7: =('Correction Blank'!D7-$B$19)/$B$18 -> 0.52325581 | E7: =('Correction Blank'!E7-$B$19)/$B$18 -> 0.81395349 | F7: =('Correction Blank'!F7-$B$19)/$B$18 -> 0.98837209 | G7: =('Correction Blank'!G7-$B$19)/$B$18 -> 1.1627907 | H7: =('Correction Blank'!H7-$B$19)/$B$18 -> 1.2790698 | I7: =('Correction Blank'!I7-$B$19)/$B$18 -> 1.3953488 | J7: =('Correction Blank'!J7-$B$19)/$B$18 -> 1.5116279 | ... Z7: =('Correction Blank'!Z7-$B$19)/$B$18 -> 3.255814
B8: P23-DCF-4 | C8: =('Correction Blank'!C8-$B$19)/$B$18 -> 0.52325581 | D8: =('Correction Blank'!D8-$B$19)/$B$18 -> 0.52325581 | E8: =('Correction Blank'!E8-$B$19)/$B$18 -> 0.69767442 | F8: =('Correction Blank'!F8-$B$19)/$B$18 -> 0.75581395 | G8: =('Correction Blank'!G8-$B$19)/$B$18 -> 0.87209302 | H8: =('Correction Blank'!H8-$B$19)/$B$18 -> 0.98837209 | I8: =('Correction Blank'!I8-$B$19)/$B$18 -> 1.1627907 | J8: =('Correction Blank'!J8-$B$19)/$B$18 -> 1.1627907 | ... Z8: =('Correction Blank'!Z8-$B$19)/$B$18 -> 2.4418605
C15: y = 0.0172x + 0.002
A18: a | B18: 0.0172
A19: b | B19: 0.002
A20: Vol.Media (ml) | B20: 20

Sheet Cumulative Release
A1: HTDPA P15 – Sampling-Corrected Cumulative Methylene Blue Release
A2: P23-DCF(Poloxamer 407), 1 µm PET membrane, 30 RPM, 28 °C, n=4 channels
A4: Calculation inputs
A5: Receptor volume (mL) | B5: =Info!B37 -> 19.3 | D5: Equation | E5: Qn = V·Cn + Vs·SUM(C1:Cn-1)
B6: =Info!B38 -> 19.7
B7: =Info!B39 -> 19.5
B8: =Info!B40 -> 24.1
A10: Sample volume replaced (mL) | B10: 0.25 | D10: Interpretation | E10: Current amount in the 20 mL receptor + all MB removed in previous 250 µL samples. The current sample is not added separately.
A11: Initial MB in donor (µg) | B11: 250 | D11: Data handling | E11: Concentrations are linked directly from Conversions and are not truncated; negative early values are retained exactly as calculated.
A13: Measured concentration (µg/mL)
B14: Time (min) | C14: =Conversions!C4 -> 17 | D14: =Conversions!D4 -> 34 | E14: =Conversions!E4 -> 51 | F14: =Conversions!F4 -> 68 | G14: =Conversions!G4 -> 85 | H14: =Conversions!H4 -> 102 | I14: =Conversions!I4 -> 119 | J14: =Conversions!J4 -> 136 | ... N14: =Conversions!N4 -> 204 | O14: =N14+17 -> 221 | P14: =O14+17 -> 238 | Q14: =P14+17 -> 255 | R14: =Q14+17 -> 272 | S14: =R14+17 -> 289 | T14: =S14+17 -> 306 | U14: =T14+17 -> 323 | V14: =U14+17 -> 340 | ... Z14: =Y14+17 -> 408
B15: P23-DCF-1 | C15: =Conversions!C5 -> 0.52325581 | D15: =Conversions!D5 -> 0.69767442 | E15: =Conversions!E5 -> 0.87209302 | F15: =Conversions!F5 -> 1.1627907 | G15: =Conversions!G5 -> 1.3372093 | H15: =Conversions!H5 -> 1.3953488 | I15: =Conversions!I5 -> 1.5697674 | J15: =Conversions!J5 -> 1.627907 | ... Z15: =Conversions!Z5 -> 3.255814
B16: P23-DCF-2 | C16: =Conversions!C6 -> 1.3372093 | D16: =Conversions!D6 -> 1.3372093 | E16: =Conversions!E6 -> 1.1627907 | F16: =Conversions!F6 -> 1.0465116 | G16: =Conversions!G6 -> 1.3953488 | H16: =Conversions!H6 -> 1.5697674 | I16: =Conversions!I6 -> 1.627907 | J16: =Conversions!J6 -> 1.8604651 | ... Z16: =Conversions!Z6 -> 3.4883721
B17: P23-DCF-3 | C17: =Conversions!C7 -> 0.52325581 | D17: =Conversions!D7 -> 0.52325581 | E17: =Conversions!E7 -> 0.81395349 | F17: =Conversions!F7 -> 0.98837209 | G17: =Conversions!G7 -> 1.1627907 | H17: =Conversions!H7 -> 1.2790698 | I17: =Conversions!I7 -> 1.3953488 | J17: =Conversions!J7 -> 1.5116279 | ... Z17: =Conversions!Z7 -> 3.255814
B18: P23-DCF-4 | C18: =Conversions!C8 -> 0.52325581 | D18: =Conversions!D8 -> 0.52325581 | E18: =Conversions!E8 -> 0.69767442 | F18: =Conversions!F8 -> 0.75581395 | G18: =Conversions!G8 -> 0.87209302 | H18: =Conversions!H8 -> 0.98837209 | I18: =Conversions!I8 -> 1.1627907 | J18: =Conversions!J8 -> 1.1627907 | ... L18: =Conversions!L8 -> 1.3372093 | N18: =Conversions!N8 -> 1.6860465 | O18: =Conversions!O8 -> 1.627907 | P18: =Conversions!P8 -> 1.8604651 | Q18: =Conversions!Q8 -> 1.744186 | R18: =Conversions!R8 -> 1.744186 | S18: =Conversions!S8 -> 1.9186047 | T18: =Conversions!T8 -> 1.9767442 | U18: =Conversions!U8 -> 2.0348837 | ... Z18: =Conversions!Z8 -> 2.4418605
A20: Sampling-corrected cumulative release (µg)
B21: Time (min) | C21: =C14 -> 17 | D21: =D14 -> 34 | E21: =E14 -> 51 | F21: =F14 -> 68 | G21: =G14 -> 85 | H21: =H14 -> 102 | I21: =I14 -> 119 | J21: =J14 -> 136 | ... Z21: =Z14 -> 408
B22: P23-DCF-1 | C22: =C15*$B$5 -> 10.098837 | D22: =D15*$B$5+$B$10*SUM($C15:C15) -> 13.59593 | E22: =E15*$B$5+$B$10*SUM($C15:D15) -> 17.136628 | F22: =F15*$B$5+$B$10*SUM($C15:E15) -> 22.965116 | G22: =G15*$B$5+$B$10*SUM($C15:F15) -> 26.622093 | H22: =H15*$B$5+$B$10*SUM($C15:G15) -> 28.078488 | I22: =I15*$B$5+$B$10*SUM($C15:H15) -> 31.793605 | J22: =J15*$B$5+$B$10*SUM($C15:I15) -> 33.30814 | K22: =K15*$B$5+$B$10*SUM($C15:J15) -> 35.959302 | ... Z22: =Z15*$B$5+$B$10*SUM($C15:Y15) -> 74.770349
B23: P23-DCF-2 | C23: =C16*$B$6 -> 26.343023 | D23: =D16*$B$5+$B$10*SUM($C16:C16) -> 26.142442 | E23: =E16*$B$6+$B$10*SUM($C16:D16) -> 23.575581 | F23: =F16*$B$6+$B$10*SUM($C16:E16) -> 21.575581 | G23: =G16*$B$6+$B$10*SUM($C16:F16) -> 28.709302 | H23: =H16*$B$6+$B$10*SUM($C16:G16) -> 32.494186 | I23: =I16*$B$6+$B$10*SUM($C16:H16) -> 34.031977 | J23: =J16*$B$6+$B$10*SUM($C16:I16) -> 39.020349 | K23: =K16*$B$6+$B$10*SUM($C16:J16) -> 40.630814 | L23: =L16*$B$6+$B$10*SUM($C16:K16) -> 42.255814 | ... Z23: =Z16*$B$6+$B$10*SUM($C16:Y16) -> 81.642442
B24: P23-DCF-3 | C24: =C17*$B$7 -> 10.203488 | D24: =D17*$B$5+$B$10*SUM($C17:C17) -> 10.229651 | E24: =E17*$B$7+$B$10*SUM($C17:D17) -> 16.133721 | F24: =F17*$B$7+$B$10*SUM($C17:E17) -> 19.738372 | G24: =G17*$B$7+$B$10*SUM($C17:F17) -> 23.386628 | H24: =H17*$B$7+$B$10*SUM($C17:G17) -> 25.944767 | I24: =I17*$B$7+$B$10*SUM($C17:H17) -> 28.531977 | J24: =J17*$B$7+$B$10*SUM($C17:I17) -> 31.148256 | K24: =K17*$B$7+$B$10*SUM($C17:J17) -> 29.258721 | L24: =L17*$B$7+$B$10*SUM($C17:K17) -> 36.409884 | ... Z24: =Z17*$B$7+$B$10*SUM($C17:Y17) -> 74.331395
B25: P23-DCF-4 | C25: =C18*$B$8 -> 12.610465 | D25: =D18*$B$5+$B$10*SUM($C18:C18) -> 10.229651 | E25: =E18*$B$8+$B$10*SUM($C18:D18) -> 17.075581 | F25: =F18*$B$8+$B$10*SUM($C18:E18) -> 18.651163 | G25: =G18*$B$8+$B$10*SUM($C18:F18) -> 21.642442 | H25: =H18*$B$8+$B$10*SUM($C18:G18) -> 24.662791 | I25: =I18*$B$8+$B$10*SUM($C18:H18) -> 29.113372 | J25: =J18*$B$8+$B$10*SUM($C18:I18) -> 29.40407 | K25: =K18*$B$8+$B$10*SUM($C18:J18) -> 31.09593 | L25: =L18*$B$8+$B$10*SUM($C18:K18) -> 34.203488 | N25: =N18*$B$8+$B$10*SUM($C18:M18) -> 42.944767 | O25: =O18*$B$8+$B$10*SUM($C18:N18) -> 41.965116 | P25: =P18*$B$8+$B$10*SUM($C18:O18) -> 47.976744 | Q25: =Q18*$B$8+$B$10*SUM($C18:P18) -> 45.639535 | R25: =R18*$B$8+$B$10*SUM($C18:Q18) -> 46.075581 | S25: =S18*$B$8+$B$10*SUM($C18:R18) -> 50.715116 | T25: =T18*$B$8+$B$10*SUM($C18:S18) -> 52.59593 | U25: =U18*$B$8+$B$10*SUM($C18:T18) -> 54.491279 | ... Z25: =Z18*$B$8+$B$10*SUM($C18:Y18) -> 67.075581
A28: Sampling-corrected cumulative release (% of 250 µg donor dose)
B29: Time (min) | C29: =C14 -> 17 | D29: =D14 -> 34 | E29: =E14 -> 51 | F29: =F14 -> 68 | G29: =G14 -> 85 | H29: =H14 -> 102 | I29: =I14 -> 119 | J29: =J14 -> 136 | ... Z29: =Z14 -> 408
B30: P23-DCF-1 | C30: =C22/$B$11*100 -> 4.0395349 | D30: =D22/$B$11*100 -> 5.4383721 | E30: =E22/$B$11*100 -> 6.8546512 | F30: =F22/$B$11*100 -> 9.1860465 | G30: =G22/$B$11*100 -> 10.648837 | H30: =H22/$B$11*100 -> 11.231395 | I30: =I22/$B$11*100 -> 12.717442 | J30: =J22/$B$11*100 -> 13.323256 | ... Z30: =Z22/$B$11*100 -> 29.90814
B31: P23-DCF-2 | C31: =C23/$B$11*100 -> 10.537209 | D31: =D23/$B$11*100 -> 10.456977 | E31: =E23/$B$11*100 -> 9.4302326 | F31: =F23/$B$11*100 -> 8.6302326 | G31: =G23/$B$11*100 -> 11.483721 | H31: =H23/$B$11*100 -> 12.997674 | I31: =I23/$B$11*100 -> 13.612791 | J31: =J23/$B$11*100 -> 15.60814 | ... Z31: =Z23/$B$11*100 -> 32.656977
B32: P23-DCF-3 | C32: =C24/$B$11*100 -> 4.0813953 | D32: =D24/$B$11*100 -> 4.0918605 | E32: =E24/$B$11*100 -> 6.4534884 | F32: =F24/$B$11*100 -> 7.8953488 | G32: =G24/$B$11*100 -> 9.3546512 | H32: =H24/$B$11*100 -> 10.377907 | I32: =I24/$B$11*100 -> 11.412791 | J32: =J24/$B$11*100 -> 12.459302 | ... Z32: =Z24/$B$11*100 -> 29.732558
B33: P23-DCF-4 | C33: =C25/$B$11*100 -> 5.044186 | D33: =D25/$B$11*100 -> 4.0918605 | E33: =E25/$B$11*100 -> 6.8302326 | F33: =F25/$B$11*100 -> 7.4604651 | G33: =G25/$B$11*100 -> 8.6569767 | H33: =H25/$B$11*100 -> 9.8651163 | I33: =I25/$B$11*100 -> 11.645349 | J33: =J25/$B$11*100 -> 11.761628 | ... L33: =L25/$B$11*100 -> 13.681395 | N33: =N25/$B$11*100 -> 17.177907 | O33: =O25/$B$11*100 -> 16.786047 | P33: =P25/$B$11*100 -> 19.190698 | Q33: =Q25/$B$11*100 -> 18.255814 | R33: =R25/$B$11*100 -> 18.430233 | S33: =S25/$B$11*100 -> 20.286047 | T33: =T25/$B$11*100 -> 21.038372 | U33: =U25/$B$11*100 -> 21.796512 | ... Z33: =Z25/$B$11*100 -> 26.830233
A36: P15 All CH | B36: Average (%) | C36: =AVERAGE(C30:C33) -> 5.9255814 | D36: =AVERAGE(D30:D33) -> 6.0197674 | E36: =AVERAGE(E30:E33) -> 7.3921512 | F36: =AVERAGE(F30:F33) -> 8.2930233 | G36: =AVERAGE(G30:G33) -> 10.036047 | H36: =AVERAGE(H30:H33) -> 11.118023 | I36: =AVERAGE(I30:I33) -> 12.347093 | J36: =AVERAGE(J30:J33) -> 13.288081 | ... Z36: =AVERAGE(Z30:Z33) -> 29.781977
B37: S.D. (%) | C37: =STDEV(C30:C33) -> 3.1092423 | D37: =STDEV(D30:D33) -> 3.025475 | E37: =STDEV(E30:E33) -> 1.3710729 | F37: =STDEV(F30:F33) -> 0.76648519 | G37: =STDEV(G30:G33) -> 1.2698303 | H37: =STDEV(H30:H33) -> 1.3739832 | I37: =STDEV(I30:I33) -> 1.01727 | J37: =STDEV(J30:J33) -> 1.6734039 | ... Z37: =STDEV(Z30:Z33) -> 2.3802505
B38: C.V. (%) | C38: =IFERROR(C37/C36*100,"") -> 52.471515 | D38: =IFERROR(D37/D36*100,"") -> 50.259002 | E38: =IFERROR(E37/E36*100,"") -> 18.547684 | F38: =IFERROR(F37/F36*100,"") -> 9.2425304 | G38: =IFERROR(G37/G36*100,"") -> 12.652694 | H38: =IFERROR(H37/H36*100,"") -> 12.358161 | I38: =IFERROR(I37/I36*100,"") -> 8.2389431 | J38: =IFERROR(J37/J36*100,"") -> 12.59327 | ... Z38: =IFERROR(Z37/Z36*100,"") -> 7.9922517
A40: Note | B40: The existing Conversions sheet applies sampling correction only at selected cells. This sheet uses the cumulative correction at every time point and leaves the original sheet unchanged.

Sheet STD DCF
B4: Tube | C4: Target | D4: µg/mL | E4: 1 | F4: 2 | G4: 3 | H4: Av. | I4: Corrected
B5: A | C5: 50 ug/mL | D5: 50 | E5: 0.897 | F5: 0.966 | G5: 0.91 | H5: =AVERAGE(E5:G5) -> 0.92433333 | I5: =H5-$H$16 -> 0.87333333
B6: B | C6: 40 ug/mL | D6: 40 | E6: 0.726 | F6: 0.73 | G6: 0.729 | H6: =AVERAGE(E6:G6) -> 0.72833333 | I6: =H6-$H$16 -> 0.67733333
B7: C | C7: 30 ug/mL | D7: 30 | E7: 0.559 | F7: 0.562 | G7: 0.56 | H7: =AVERAGE(E7:G7) -> 0.56033333 | I7: =H7-$H$16 -> 0.50933333
B8: D | C8: 25 ug/mL | D8: 25 | E8: 0.474 | F8: 0.478 | G8: 0.472 | H8: =AVERAGE(E8:G8) -> 0.47466667 | I8: =H8-$H$16 -> 0.42366667
B9: E | C9: 20 ug/mL | D9: 20 | E9: 0.392 | F9: 0.397 | G9: 0.393 | H9: =AVERAGE(E9:G9) -> 0.394 | I9: =H9-$H$16 -> 0.343
B10: F | C10: 15 ug/mL | D10: 15 | E10: 0.315 | F10: 0.324 | G10: 0.319 | H10: =AVERAGE(E10:G10) -> 0.31933333 | I10: =H10-$H$16 -> 0.26833333
B11: G | C11: 10 ug/mL | D11: 10 | E11: 0.227 | F11: 0.23 | G11: 0.235 | H11: =AVERAGE(E11:G11) -> 0.23066667 | I11: =H11-$H$16 -> 0.17966667
B12: H | C12: 5 ug/mL | D12: 5 | E12: 0.14 | F12: 0.141 | G12: 0.142 | H12: =AVERAGE(E12:G12) -> 0.141 | I12: =H12-$H$16 -> 0.09
B13: I | C13: 3 ug/mL | D13: 3 | E13: 0.103 | F13: 0.103 | G13: 0.103 | H13: =AVERAGE(E13:G13) -> 0.103 | I13: =H13-$H$16 -> 0.052
B14: J | C14: 1 ug/mL | D14: 1 | E14: 0.068 | F14: 0.069 | G14: 0.068 | H14: =AVERAGE(E14:G14) -> 0.068333333 | I14: =H14-$H$16 -> 0.017333333
B15: K | C15: 0.5 ug/mL | D15: 0.5 | E15: 0.064 | F15: 0.063 | G15: 0.063 | H15: =AVERAGE(E15:G15) -> 0.063333333 | I15: =H15-$H$16 -> 0.012333333
B16: BLANK | C16: Blank | D16: 0 | E16: 0.051 | F16: 0.051 | G16: 0.051 | H16: =AVERAGE(E16:G16) -> 0.051 | I16: =H16-$H$16 -> 0
