Workbook

Sheet Sheet 1
A1: P23MB-10-28-15RPM | C1: P23(Poloxamer 407), 1 µm PET membrane, 15RPM,28 °C, n=4 channels
B3: 1 | C3: 2 | D3: 3 | E3: 4 | F3: 5 | G3: 6 | H3: 7 | I3: 8 | J3: 9 | K3: 10 | L3: 11 | M3: 12
A4: A | B4: 0.077 | C4: 0.121 | D4: 0.14 | E4: 0.162 | F4: 0.179 | G4: 0.197 | H4: 0.21 | I4: 0.219 | J4: 0.233 | K4: 0.245 | L4: 0.26 | M4: 0.272 | N4: 660
A5: B | B5: 0.079 | C5: 0.113 | D5: 0.134 | E5: 0.151 | F5: 0.169 | G5: 0.181 | H5: 0.191 | I5: 0.197 | J5: 0.21 | K5: 0.22 | L5: 0.235 | M5: 0.249 | N5: 660
A6: C | B6: 0.078 | C6: 0.111 | D6: 0.142 | E6: 0.152 | F6: 0.168 | G6: 0.18 | H6: 0.189 | I6: 0.198 | J6: 0.213 | K6: 0.221 | L6: 0.235 | M6: 0.249 | N6: 660
A7: D | B7: 0.077 | C7: 0.107 | D7: 0.131 | E7: 0.14 | F7: 0.148 | G7: 0.157 | H7: 0.167 | I7: 0.18 | J7: 0.184 | K7: 0.197 | L7: 0.207 | M7: 0.22 | N7: 660
A8: E | B8: 0.281 | C8: 0.298 | D8: 0.319 | E8: 0.325 | F8: 0.343 | G8: 0.35 | H8: 0.36 | I8: 0.382 | J8: 0.397 | K8: 0.417 | L8: 0.442 | M8: 0.479 | N8: 660
A9: F | B9: 0.271 | C9: 0.283 | D9: 0.292 | E9: 0.304 | F9: 0.321 | G9: 0.334 | H9: 0.339 | I9: 0.359 | J9: 0.385 | K9: 0.407 | L9: 0.434 | M9: 0.487 | N9: 660
A10: G | B10: 0.267 | C10: 0.276 | D10: 0.293 | E10: 0.303 | F10: 0.315 | G10: 0.33 | H10: 0.337 | I10: 0.354 | J10: 0.371 | K10: 0.388 | L10: 0.408 | M10: 0.465 | N10: 660
A11: H | B11: 0.238 | C11: 0.248 | D11: 0.259 | E11: 0.269 | F11: 0.283 | G11: 0.3 | H11: 0.312 | I11: 0.337 | J11: 0.345 | K11: 0.351 | L11: 0.38 | M11: 0.441 | N11: 660

Sheet Info
C1: P23(Poloxamer 407), 1 µm PET membrane, 15RPM,28 °C, n=4 channels
B3: 1 | C3: 2 | D3: 3 | E3: 4 | F3: 5 | G3: 6 | H3: 7 | I3: 8 | J3: 9 | K3: 10 | L3: 11 | M3: 12
A4: A | B4: ='Sheet 1'!B4 -> 0.077 | C4: ='Sheet 1'!C4 -> 0.121 | D4: ='Sheet 1'!D4 -> 0.14 | E4: ='Sheet 1'!E4 -> 0.162 | F4: ='Sheet 1'!F4 -> 0.179 | G4: ='Sheet 1'!G4 -> 0.197 | H4: ='Sheet 1'!H4 -> 0.21 | I4: ='Sheet 1'!I4 -> 0.219 | ... M4: ='Sheet 1'!M4 -> 0.272 | N4: 660
A5: B | B5: ='Sheet 1'!B5 -> 0.079 | C5: ='Sheet 1'!C5 -> 0.113 | D5: ='Sheet 1'!D5 -> 0.134 | E5: ='Sheet 1'!E5 -> 0.151 | F5: ='Sheet 1'!F5 -> 0.169 | G5: ='Sheet 1'!G5 -> 0.181 | H5: ='Sheet 1'!H5 -> 0.191 | I5: ='Sheet 1'!I5 -> 0.197 | ... M5: ='Sheet 1'!M5 -> 0.249 | N5: 660
A6: C | B6: ='Sheet 1'!B6 -> 0.078 | C6: ='Sheet 1'!C6 -> 0.111 | D6: ='Sheet 1'!D6 -> 0.142 | E6: ='Sheet 1'!E6 -> 0.152 | F6: ='Sheet 1'!F6 -> 0.168 | G6: ='Sheet 1'!G6 -> 0.18 | H6: ='Sheet 1'!H6 -> 0.189 | I6: ='Sheet 1'!I6 -> 0.198 | ... M6: ='Sheet 1'!M6 -> 0.249 | N6: 660
A7: D | B7: ='Sheet 1'!B7 -> 0.077 | C7: ='Sheet 1'!C7 -> 0.107 | D7: ='Sheet 1'!D7 -> 0.131 | E7: ='Sheet 1'!E7 -> 0.14 | F7: ='Sheet 1'!F7 -> 0.148 | G7: ='Sheet 1'!G7 -> 0.157 | H7: ='Sheet 1'!H7 -> 0.167 | I7: ='Sheet 1'!I7 -> 0.18 | ... M7: ='Sheet 1'!M7 -> 0.22 | N7: 660
A8: E | B8: ='Sheet 1'!B8 -> 0.281 | C8: ='Sheet 1'!C8 -> 0.298 | D8: ='Sheet 1'!D8 -> 0.319 | E8: ='Sheet 1'!E8 -> 0.325 | F8: ='Sheet 1'!F8 -> 0.343 | G8: ='Sheet 1'!G8 -> 0.35 | H8: ='Sheet 1'!H8 -> 0.36 | I8: ='Sheet 1'!I8 -> 0.382 | ... M8: ='Sheet 1'!M8 -> 0.479 | N8: 660
A9: F | B9: ='Sheet 1'!B9 -> 0.271 | C9: ='Sheet 1'!C9 -> 0.283 | D9: ='Sheet 1'!D9 -> 0.292 | E9: ='Sheet 1'!E9 -> 0.304 | F9: ='Sheet 1'!F9 -> 0.321 | G9: ='Sheet 1'!G9 -> 0.334 | H9: ='Sheet 1'!H9 -> 0.339 | I9: ='Sheet 1'!I9 -> 0.359 | ... M9: ='Sheet 1'!M9 -> 0.487 | N9: 660
A10: G | B10: ='Sheet 1'!B10 -> 0.267 | C10: ='Sheet 1'!C10 -> 0.276 | D10: ='Sheet 1'!D10 -> 0.293 | E10: ='Sheet 1'!E10 -> 0.303 | F10: ='Sheet 1'!F10 -> 0.315 | G10: ='Sheet 1'!G10 -> 0.33 | H10: ='Sheet 1'!H10 -> 0.337 | I10: ='Sheet 1'!I10 -> 0.354 | ... M10: ='Sheet 1'!M10 -> 0.465 | N10: 660
A11: H | B11: ='Sheet 1'!B11 -> 0.238 | C11: ='Sheet 1'!C11 -> 0.248 | D11: ='Sheet 1'!D11 -> 0.259 | E11: ='Sheet 1'!E11 -> 0.269 | F11: ='Sheet 1'!F11 -> 0.283 | G11: ='Sheet 1'!G11 -> 0.3 | H11: ='Sheet 1'!H11 -> 0.312 | I11: ='Sheet 1'!I11 -> 0.337 | ... M11: ='Sheet 1'!M11 -> 0.441 | N11: 660
A16: Time (min) | B16: 17 | C16: =B16+17 -> 34 | D16: =C16+17 -> 51 | E16: =D16+17 -> 68 | F16: =E16+17 -> 85 | G16: =F16+17 -> 102 | H16: =G16+17 -> 119 | I16: =H16+17 -> 136 | J16: =I16+17 -> 153 | ... M16: =L16+17 -> 204
A17: Ch1 (A) | B17: =B4 -> 0.077 | C17: =C4 -> 0.121 | D17: =D4 -> 0.14 | E17: =E4 -> 0.162 | F17: =F4 -> 0.179 | G17: =G4 -> 0.197 | H17: =H4 -> 0.21 | I17: =I4 -> 0.219 | ... M17: =M4 -> 0.272
A18: Ch2 (B) | B18: =B5 -> 0.079 | C18: =C5 -> 0.113 | D18: =D5 -> 0.134 | E18: =E5 -> 0.151 | F18: =F5 -> 0.169 | G18: =G5 -> 0.181 | H18: =H5 -> 0.191 | I18: =I5 -> 0.197 | ... M18: =M5 -> 0.249
A19: Ch3 (C) | B19: =B6 -> 0.078 | C19: =C6 -> 0.111 | D19: =D6 -> 0.142 | E19: =E6 -> 0.152 | F19: =F6 -> 0.168 | G19: =G6 -> 0.18 | H19: =H6 -> 0.189 | I19: =I6 -> 0.198 | ... M19: =M6 -> 0.249
A20: Ch4 (D) | B20: =B7 -> 0.077 | C20: =C7 -> 0.107 | D20: =D7 -> 0.131 | E20: =E7 -> 0.14 | F20: =F7 -> 0.148 | G20: =G7 -> 0.157 | H20: =H7 -> 0.167 | I20: =I7 -> 0.18 | ... M20: =M7 -> 0.22
A22: Time (min) | B22: =17+M16 -> 221 | C22: =B22+17 -> 238 | D22: =C22+17 -> 255 | E22: =D22+17 -> 272 | F22: =E22+17 -> 289 | G22: =F22+17 -> 306 | H22: =G22+17 -> 323 | I22: =H22+17 -> 340 | J22: =I22+17 -> 357 | ... M22: =L22+17 -> 408
A23: Ch1 (E) | B23: =B8 -> 0.281 | C23: =C8 -> 0.298 | D23: =D8 -> 0.319 | E23: =E8 -> 0.325 | F23: =F8 -> 0.343 | G23: =G8 -> 0.35 | H23: =H8 -> 0.36 | I23: =I8 -> 0.382 | ... M23: =M8 -> 0.479
A24: Ch2 (F) | B24: =B9 -> 0.271 | C24: =C9 -> 0.283 | D24: =D9 -> 0.292 | E24: =E9 -> 0.304 | F24: =F9 -> 0.321 | G24: =G9 -> 0.334 | H24: =H9 -> 0.339 | I24: =I9 -> 0.359 | ... M24: =M9 -> 0.487
A25: Ch3 (G) | B25: =B10 -> 0.267 | C25: =C10 -> 0.276 | D25: =D10 -> 0.293 | E25: =E10 -> 0.303 | F25: =F10 -> 0.315 | G25: =G10 -> 0.33 | H25: =H10 -> 0.337 | I25: =I10 -> 0.354 | ... M25: =M10 -> 0.465
A26: Ch4 (H) | B26: =B11 -> 0.238 | C26: =C11 -> 0.248 | D26: =D11 -> 0.259 | E26: =E11 -> 0.269 | F26: =F11 -> 0.283 | G26: =G11 -> 0.3 | H26: =H11 -> 0.312 | I26: =I11 -> 0.337 | ... M26: =M11 -> 0.441
A29: Formulations
A30: Ch1 | B30: P23-1
A31: Ch2 | B31: P23-2
A32: Ch3 | B32: P23-3 | N32: =5*60 -> 300
A33: Ch4 | B33: P23-4
A36: Receptor cell (ml)
A37: Ch1 | B37: 19.4
A38: Ch2 | B38: 17.4
A39: Ch3 | B39: 20
A40: Ch4 | B40: 22
A43: Donor cell (ml)
A44: Ch1 | B44: 0.5 | C44: 250 | D44: ug MB
A45: Ch2 | B45: 0.5 | C45: 250 | D45: ug MB
A46: Ch3 | B46: 0.5 | C46: 250 | D46: ug MB
A47: Ch4 | B47: 0.5 | C47: 250 | D47: ug MB
A50: Flow RMSP (Q+) / (Q-) ml/min | C50: 15RPM
A51: Ch1
A52: Ch2
A53: Ch3
A54: Ch4
...

Sheet Correction Blank
A3: Correction O.D
B4: Time (min) | C4: =17 -> 17 | D4: =C4+17 -> 34 | E4: =D4+17 -> 51 | F4: =E4+17 -> 68 | G4: =F4+17 -> 85 | H4: =G4+17 -> 102 | I4: =H4+17 -> 119 | J4: =I4+17 -> 136 | K4: =J4+17 -> 153 | ... Z4: =Y4+17 -> 408
B5: =Info!B30 -> P23-1 | C5: =Info!B17-0.045 -> 0.032 | D5: =Info!C17-0.045 -> 0.076 | E5: =Info!D17-0.045 -> 0.095 | F5: =Info!E17-0.045 -> 0.117 | G5: =Info!F17-0.045 -> 0.134 | H5: =Info!G17-0.045 -> 0.152 | I5: =Info!H17-0.045 -> 0.165 | J5: =Info!I17-0.045 -> 0.174 | ... N5: =Info!M17-0.045 -> 0.227 | O5: =Info!B23-0.045 -> 0.236 | P5: =Info!C23-0.045 -> 0.253 | Q5: =Info!D23-0.045 -> 0.274 | R5: =Info!E23-0.045 -> 0.28 | S5: =Info!F23-0.045 -> 0.298 | T5: =Info!G23-0.045 -> 0.305 | U5: =Info!H23-0.045 -> 0.315 | V5: =Info!I23-0.045 -> 0.337 | ... Z5: =Info!M23-0.045 -> 0.434
B6: =Info!B31 -> P23-2 | C6: =Info!B18-0.045 -> 0.034 | D6: =Info!C18-0.045 -> 0.068 | E6: =Info!D18-0.045 -> 0.089 | F6: =Info!E18-0.045 -> 0.106 | G6: =Info!F18-0.045 -> 0.124 | H6: =Info!G18-0.045 -> 0.136 | I6: =Info!H18-0.045 -> 0.146 | J6: =Info!I18-0.045 -> 0.152 | ... N6: =Info!M18-0.045 -> 0.204 | O6: =Info!B24-0.045 -> 0.226 | P6: =Info!C24-0.045 -> 0.238 | Q6: =Info!D24-0.045 -> 0.247 | R6: =Info!E24-0.045 -> 0.259 | S6: =Info!F24-0.045 -> 0.276 | T6: =Info!G24-0.045 -> 0.289 | U6: =Info!H24-0.045 -> 0.294 | V6: =Info!I24-0.045 -> 0.314 | ... Z6: =Info!M24-0.045 -> 0.442
B7: =Info!B32 -> P23-3 | C7: =Info!B19-0.045 -> 0.033 | D7: =Info!C19-0.045 -> 0.066 | E7: =Info!D19-0.045 -> 0.097 | F7: =Info!E19-0.045 -> 0.107 | G7: =Info!F19-0.045 -> 0.123 | H7: =Info!G19-0.045 -> 0.135 | I7: =Info!H19-0.045 -> 0.144 | J7: =Info!I19-0.045 -> 0.153 | ... N7: =Info!M19-0.045 -> 0.204 | O7: =Info!B25-0.045 -> 0.222 | P7: =Info!C25-0.045 -> 0.231 | Q7: =Info!D25-0.045 -> 0.248 | R7: =Info!E25-0.045 -> 0.258 | S7: =Info!F25-0.045 -> 0.27 | T7: =Info!G25-0.045 -> 0.285 | U7: =Info!H25-0.045 -> 0.292 | V7: =Info!I25-0.045 -> 0.309 | ... Z7: =Info!M25-0.045 -> 0.42
B8: =Info!B33 -> P23-4 | C8: =Info!B20-0.045 -> 0.032 | D8: =Info!C20-0.045 -> 0.062 | E8: =Info!D20-0.045 -> 0.086 | F8: =Info!E20-0.045 -> 0.095 | G8: =Info!F20-0.045 -> 0.103 | H8: =Info!G20-0.045 -> 0.112 | I8: =Info!H20-0.045 -> 0.122 | J8: =Info!I20-0.045 -> 0.135 | ... N8: =Info!M20-0.045 -> 0.175 | O8: =Info!B26-0.045 -> 0.193 | P8: =Info!C26-0.045 -> 0.203 | Q8: =Info!D26-0.045 -> 0.214 | R8: =Info!E26-0.045 -> 0.224 | S8: =Info!F26-0.045 -> 0.238 | T8: =Info!G26-0.045 -> 0.255 | U8: =Info!H26-0.045 -> 0.267 | V8: =Info!I26-0.045 -> 0.292 | ... Z8: =Info!M26-0.045 -> 0.396

Sheet Conversions
C1: P23(Poloxamer 407), 1 µm PET membrane, 15RPM,28 °C, n=4 channels
A3: Convert to MB content (ug)
B4: Time (min) | C4: =17 -> 17 | D4: =C4+17 -> 34 | E4: =D4+17 -> 51 | F4: =E4+17 -> 68 | G4: =F4+17 -> 85 | H4: =G4+17 -> 102 | I4: =H4+17 -> 119 | J4: =I4+17 -> 136 | K4: =J4+17 -> 153 | ... Z4: =Y4+17 -> 408
B5: =Info!B30 -> P23-1 | C5: =('Correction Blank'!C5-$B$13)/$B$12 -> -0.39832636 | D5: =('Correction Blank'!D5-$B$13)/$B$12 -> -0.030125523 | E5: =('Correction Blank'!E5-$B$13)/$B$12 -> 0.12887029 | F5: =('Correction Blank'!F5-$B$13)/$B$12 -> 0.31297071 | G5: =('Correction Blank'!G5-$B$13)/$B$12 -> 0.45523013 | H5: =('Correction Blank'!H5-$B$13)/$B$12 -> 0.60585774 | I5: =('Correction Blank'!I5-$B$13)/$B$12 -> 0.71464435 | J5: =('Correction Blank'!J5-$B$13)/$B$12 -> 0.78995816 | ... Z5: =('Correction Blank'!Z5-$B$13)/$B$12 -> 2.9656904
B6: =Info!B31 -> P23-2 | C6: =('Correction Blank'!C6-$B$13)/$B$12 -> -0.38158996 | D6: =('Correction Blank'!D6-$B$13)/$B$12 -> -0.09707113 | E6: =('Correction Blank'!E6-$B$13)/$B$12 -> 0.078661088 | F6: =('Correction Blank'!F6-$B$13)/$B$12 -> 0.2209205 | G6: =('Correction Blank'!G6-$B$13)/$B$12 -> 0.37154812 | H6: =('Correction Blank'!H6-$B$13)/$B$12 -> 0.47196653 | I6: =('Correction Blank'!I6-$B$13)/$B$12 -> 0.55564854 | J6: =('Correction Blank'!J6-$B$13)/$B$12 -> 0.60585774 | ... Z6: =('Correction Blank'!Z6-$B$13)/$B$12 -> 3.032636
B7: =Info!B32 -> P23-3 | C7: =('Correction Blank'!C7-$B$13)/$B$12 -> -0.38995816 | D7: =('Correction Blank'!D7-$B$13)/$B$12 -> -0.11380753 | E7: =('Correction Blank'!E7-$B$13)/$B$12 -> 0.14560669 | F7: =('Correction Blank'!F7-$B$13)/$B$12 -> 0.2292887 | G7: =('Correction Blank'!G7-$B$13)/$B$12 -> 0.36317992 | H7: =('Correction Blank'!H7-$B$13)/$B$12 -> 0.46359833 | I7: =('Correction Blank'!I7-$B$13)/$B$12 -> 0.53891213 | J7: =('Correction Blank'!J7-$B$13)/$B$12 -> 0.61422594 | ... Z7: =('Correction Blank'!Z7-$B$13)/$B$12 -> 2.8485356
B8: =Info!B33 -> P23-4 | C8: =('Correction Blank'!C8-$B$13)/$B$12 -> -0.39832636 | D8: =('Correction Blank'!D8-$B$13)/$B$12 -> -0.14728033 | E8: =('Correction Blank'!E8-$B$13)/$B$12 -> 0.053556485 | F8: =('Correction Blank'!F8-$B$13)/$B$12 -> 0.12887029 | G8: =('Correction Blank'!G8-$B$13)/$B$12 -> 0.1958159 | H8: =('Correction Blank'!H8-$B$13)/$B$12 -> 0.27112971 | I8: =('Correction Blank'!I8-$B$13)/$B$12 -> 0.35481172 | J8: =('Correction Blank'!J8-$B$13)/$B$12 -> 0.46359833 | ... Z8: =('Correction Blank'!Z8-$B$13)/$B$12 -> 2.6476987
A11: Standard Curve | B11: MB
A12: a | B12: 0.1195
A13: b | B13: 0.0796
A14: Vol.Media (ml) | B14: 20

Sheet Cumulative Release
A1: HTDPA P15 – Sampling-Corrected Cumulative Methylene Blue Release
A2: P23(Poloxamer 407), 1 µm PET membrane, 15RPM,28 °C, n=4 channels
A3: EDIT
A4: Calculation inputs
A5: Receptor volume (mL) | B5: 18.4 | D5: Equation | E5: Qn = V·Cn + Vs·SUM(C1:Cn-1)
B6: 20
B7: 20
B8: 22
A9: Sample volume replaced (mL) | B9: 0.25 | D9: Interpretation | E9: Current amount in the 20 mL receptor + all MB removed in previous 250 µL samples. The current sample is not added separately.
A10: Initial MB in donor (µg) | B10: 250 | D10: Data handling | E10: Concentrations are linked directly from Conversions and are not truncated; negative early values are retained exactly as calculated.
A12: Measured concentration (µg/mL)
B13: Time (min) | C13: =Conversions!C4 -> 17 | D13: =Conversions!D4 -> 34 | E13: =Conversions!E4 -> 51 | F13: =Conversions!F4 -> 68 | G13: =Conversions!G4 -> 85 | H13: =Conversions!H4 -> 102 | I13: =Conversions!I4 -> 119 | J13: =Conversions!J4 -> 136 | ... Z13: =Conversions!Z4 -> 408
B14: =Conversions!B5 -> P23-1 | C14: =Conversions!C5 -> -0.39832636 | D14: =Conversions!D5 -> -0.030125523 | E14: =Conversions!E5 -> 0.12887029 | F14: =Conversions!F5 -> 0.31297071 | G14: =Conversions!G5 -> 0.45523013 | H14: =Conversions!H5 -> 0.60585774 | I14: =Conversions!I5 -> 0.71464435 | ... Z14: =Conversions!Z5 -> 2.9656904
B15: =Conversions!B6 -> P23-2 | C15: =Conversions!C6 -> -0.38158996 | D15: =Conversions!D6 -> -0.09707113 | E15: =Conversions!E6 -> 0.078661088 | F15: =Conversions!F6 -> 0.2209205 | G15: =Conversions!G6 -> 0.37154812 | H15: =Conversions!H6 -> 0.47196653 | I15: =Conversions!I6 -> 0.55564854 | ... Z15: =Conversions!Z6 -> 3.032636
B16: =Conversions!B7 -> P23-3 | C16: =Conversions!C7 -> -0.38995816 | D16: =Conversions!D7 -> -0.11380753 | E16: =Conversions!E7 -> 0.14560669 | F16: =Conversions!F7 -> 0.2292887 | G16: =Conversions!G7 -> 0.36317992 | H16: =Conversions!H7 -> 0.46359833 | I16: =Conversions!I7 -> 0.53891213 | ... Z16: =Conversions!Z7 -> 2.8485356
B17: =Conversions!B8 -> P23-4 | C17: =Conversions!C8 -> -0.39832636 | D17: =Conversions!D8 -> -0.14728033 | E17: =Conversions!E8 -> 0.053556485 | F17: =Conversions!F8 -> 0.12887029 | G17: =Conversions!G8 -> 0.1958159 | H17: =Conversions!H8 -> 0.27112971 | I17: =Conversions!I8 -> 0.35481172 | ... Z17: =Conversions!Z8 -> 2.6476987
A19: Sampling-corrected cumulative release (µg)
B20: Time (min) | C20: =C13 -> 17 | D20: =D13 -> 34 | E20: =E13 -> 51 | F20: =F13 -> 68 | G20: =G13 -> 85 | H20: =H13 -> 102 | I20: =I13 -> 119 | J20: =J13 -> 136 | ... Z20: =Z13 -> 408
B21: =B14 -> P23-1 | C21: =C14*$B$5 -> -7.329205 | D21: =D14*$B$5+$B$9*SUM($C14:C14) -> -0.65389121 | E21: =E14*$B$5+$B$9*SUM($C14:D14) -> 2.2641004 | F21: =F14*$B$5+$B$9*SUM($C14:E14) -> 5.6837657 | G21: =G14*$B$5+$B$9*SUM($C14:F14) -> 8.3795816 | H21: =H14*$B$5+$B$9*SUM($C14:G14) -> 11.264937 | I21: =I14*$B$5+$B$9*SUM($C14:H14) -> 13.418075 | J21: =J14*$B$5+$B$9*SUM($C14:I14) -> 14.98251 | K21: =K14*$B$5+$B$9*SUM($C14:J14) -> 17.335649 | ... Z21: =Z14*$B$5+$B$9*SUM($C14:Y14) -> 61.604686
B22: =B15 -> P23-2 | C22: =C15*$B$6 -> -7.6317992 | D22: =D15*$B$6+$B$9*SUM($C15:C15) -> -2.0368201 | E22: =E15*$B$6+$B$9*SUM($C15:D15) -> 1.4535565 | F22: =F15*$B$6+$B$9*SUM($C15:E15) -> 4.31841 | G22: =G15*$B$6+$B$9*SUM($C15:F15) -> 7.3861925 | H22: =H15*$B$6+$B$9*SUM($C15:G15) -> 9.4874477 | I22: =I15*$B$6+$B$9*SUM($C15:H15) -> 11.279079 | J22: =J15*$B$6+$B$9*SUM($C15:I15) -> 12.422176 | K22: =K15*$B$6+$B$9*SUM($C15:J15) -> 14.749372 | ... Z22: =Z15*$B$6+$B$9*SUM($C15:Y15) -> 66.912552
B23: =B16 -> P23-3 | C23: =C16*$B$7 -> -7.7991632 | D23: =D16*$B$7+$B$9*SUM($C16:C16) -> -2.3736402 | E23: =E16*$B$7+$B$9*SUM($C16:D16) -> 2.7861925 | F23: =F16*$B$7+$B$9*SUM($C16:E16) -> 4.4962343 | G23: =G16*$B$7+$B$9*SUM($C16:F16) -> 7.2313808 | H23: =H16*$B$7+$B$9*SUM($C16:G16) -> 9.3305439 | I23: =I16*$B$7+$B$9*SUM($C16:H16) -> 10.95272 | J23: =J16*$B$7+$B$9*SUM($C16:I16) -> 12.593724 | K23: =K16*$B$7+$B$9*SUM($C16:J16) -> 15.257741 | ... Z23: =Z16*$B$7+$B$9*SUM($C16:Y16) -> 63.06318
B24: =B17 -> P23-4 | C24: =C17*$B$8 -> -8.7631799 | D24: =D17*$B$8+$B$9*SUM($C17:C17) -> -3.339749 | E24: =E17*$B$8+$B$9*SUM($C17:D17) -> 1.041841 | F24: =F17*$B$8+$B$9*SUM($C17:E17) -> 2.7121339 | G24: =G17*$B$8+$B$9*SUM($C17:F17) -> 4.2171548 | H24: =H17*$B$8+$B$9*SUM($C17:G17) -> 5.9230126 | I24: =I17*$B$8+$B$9*SUM($C17:H17) -> 7.8317992 | J24: =J17*$B$8+$B$9*SUM($C17:I17) -> 10.313808 | K24: =K17*$B$8+$B$9*SUM($C17:J17) -> 11.166109 | ... Z24: =Z17*$B$8+$B$9*SUM($C17:Y17) -> 63.210042
A26: Sampling-corrected cumulative release (% of 250 µg donor dose)
B27: Time (min) | C27: =C13 -> 17 | D27: =D13 -> 34 | E27: =E13 -> 51 | F27: =F13 -> 68 | G27: =G13 -> 85 | H27: =H13 -> 102 | I27: =I13 -> 119 | J27: =J13 -> 136 | ... Z27: =Z13 -> 408
B28: =B21 -> P23-1 | C28: =C21/$B$10*100 -> -2.931682 | D28: =D21/$B$10*100 -> -0.26155649 | E28: =E21/$B$10*100 -> 0.90564017 | F28: =F21/$B$10*100 -> 2.2735063 | G28: =G21/$B$10*100 -> 3.3518326 | H28: =H21/$B$10*100 -> 4.5059749 | I28: =I21/$B$10*100 -> 5.3672301 | J28: =J21/$B$10*100 -> 5.9930042 | ... Z28: =Z21/$B$10*100 -> 24.641874
B29: =B22 -> P23-2 | C29: =C22/$B$10*100 -> -3.0527197 | D29: =D22/$B$10*100 -> -0.81472803 | E29: =E22/$B$10*100 -> 0.58142259 | F29: =F22/$B$10*100 -> 1.727364 | G29: =G22/$B$10*100 -> 2.954477 | H29: =H22/$B$10*100 -> 3.7949791 | I29: =I22/$B$10*100 -> 4.5116318 | J29: =J22/$B$10*100 -> 4.9688703 | ... Z29: =Z22/$B$10*100 -> 26.765021
B30: =B23 -> P23-3 | C30: =C23/$B$10*100 -> -3.1196653 | D30: =D23/$B$10*100 -> -0.94945607 | E30: =E23/$B$10*100 -> 1.114477 | F30: =F23/$B$10*100 -> 1.7984937 | G30: =G23/$B$10*100 -> 2.8925523 | H30: =H23/$B$10*100 -> 3.7322176 | I30: =I23/$B$10*100 -> 4.3810879 | J30: =J23/$B$10*100 -> 5.0374895 | ... Z30: =Z23/$B$10*100 -> 25.225272
B31: =B24 -> P23-4 | C31: =C24/$B$10*100 -> -3.505272 | D31: =D24/$B$10*100 -> -1.3358996 | E31: =E24/$B$10*100 -> 0.4167364 | F31: =F24/$B$10*100 -> 1.0848536 | G31: =G24/$B$10*100 -> 1.6868619 | H31: =H24/$B$10*100 -> 2.369205 | I31: =I24/$B$10*100 -> 3.1327197 | J31: =J24/$B$10*100 -> 4.125523 | ... Z31: =Z24/$B$10*100 -> 25.284017
A33: All CH | B33: Average (%) | C33: =AVERAGE(C28:C31) -> -3.1523347 | D33: =AVERAGE(D28:D31) -> -0.84041004 | E33: =AVERAGE(E28:E31) -> 0.75456904 | F33: =AVERAGE(F28:F31) -> 1.7210544 | G33: =AVERAGE(G28:G31) -> 2.721431 | H33: =AVERAGE(H28:H31) -> 3.6005941 | I33: =AVERAGE(I28:I31) -> 4.3481674 | J33: =AVERAGE(J28:J31) -> 5.0312218 | ... Z33: =AVERAGE(Z28:Z31) -> 25.479046
B34: S.D. (%) | C34: =STDEV(C28:C31) -> 0.247819 | D34: =STDEV(D28:D31) -> 0.44464665 | E34: =STDEV(E28:E31) -> 0.31436009 | F34: =STDEV(F28:F31) -> 0.48853224 | G34: =STDEV(G28:G31) -> 0.71910415 | H34: =STDEV(H28:H31) -> 0.89277539 | I34: =STDEV(I28:I31) -> 0.92079792 | J34: =STDEV(J28:J31) -> 0.76359733 | ... Z34: =STDEV(Z28:Z31) -> 0.90499085
B35: C.V. (%) | C35: =IFERROR(C34/C33*100,"") -> -7.8614431 | D35: =IFERROR(D34/D33*100,"") -> -52.908298 | E35: =IFERROR(E34/E33*100,"") -> 41.660879 | F35: =IFERROR(F34/F33*100,"") -> 28.385636 | G35: =IFERROR(G34/G33*100,"") -> 26.423751 | H35: =IFERROR(H34/H33*100,"") -> 24.795224 | I35: =IFERROR(I34/I33*100,"") -> 21.17669 | J35: =IFERROR(J34/J33*100,"") -> 15.177175 | ... Z35: =IFERROR(Z34/Z33*100,"") -> 3.5519024
A37: Note | B37: The existing Conversions sheet applies sampling correction only at selected cells. This sheet uses the cumulative correction at every time point and leaves the original sheet unchanged.
