Workbook

Sheet Sheet 1
A1: 240426_R_7rpm_1um_500_34oC | D1: P23(Poloxamer 407), 1 µm PET membrane,7 RPM, 28 °C, n=4 channels
B3: 1 | C3: 2 | D3: 3 | E3: 4 | F3: 5 | G3: 6 | H3: 7 | I3: 8 | J3: 9 | K3: 10 | L3: 11 | M3: 12
A4: A | B4: 0.065 | C4: 0.1 | D4: 0.13 | E4: 0.151 | F4: 0.169 | G4: 0.185 | H4: 0.197 | I4: 0.216 | J4: 0.232 | K4: 0.255 | L4: 0.273 | M4: 0.287 | N4: 660
A5: B | B5: 0.066 | C5: 0.114 | D5: 0.136 | E5: 0.158 | F5: 0.169 | G5: 0.191 | H5: 0.207 | I5: 0.22 | J5: 0.235 | K5: 0.249 | L5: 0.268 | M5: 0.286 | N5: 660
A6: C | B6: 0.074 | C6: 0.105 | D6: 0.134 | E6: 0.148 | F6: 0.163 | G6: 0.169 | H6: 0.186 | I6: 0.2 | J6: 0.218 | K6: 0.239 | L6: 0.259 | M6: 0.272 | N6: 660
A7: D | B7: 0.077 | C7: 0.101 | D7: 0.131 | E7: 0.142 | F7: 0.156 | G7: 0.169 | H7: 0.183 | I7: 0.205 | J7: 0.223 | K7: 0.243 | L7: 0.254 | M7: 0.264 | N7: 660
A8: E | B8: 0.292 | C8: 0.307 | D8: 0.321 | E8: 0.333 | F8: 0.346 | G8: 0.365 | H8: 0.383 | I8: 0.402 | J8: 0.431 | K8: 0.459 | L8: 0.486 | M8: 0.516 | N8: 660
A9: F | B9: 0.291 | C9: 0.316 | D9: 0.321 | E9: 0.336 | F9: 0.35 | G9: 0.361 | H9: 0.381 | I9: 0.389 | J9: 0.41 | K9: 0.437 | L9: 0.459 | M9: 0.511 | N9: 660
A10: G | B10: 0.295 | C10: 0.305 | D10: 0.316 | E10: 0.327 | F10: 0.339 | G10: 0.345 | H10: 0.371 | I10: 0.373 | J10: 0.402 | K10: 0.422 | L10: 0.449 | M10: 0.512 | N10: 660
A11: H | B11: 0.279 | C11: 0.284 | D11: 0.307 | E11: 0.32 | F11: 0.341 | G11: 0.346 | H11: 0.368 | I11: 0.375 | J11: 0.381 | K11: 0.396 | L11: 0.433 | M11: 0.492 | N11: 660

Sheet Info
C1: P23(Poloxamer 407), 1 µm PET membrane,7 RPM, 28 °C, n=4 channels
B3: 1 | C3: 2 | D3: 3 | E3: 4 | F3: 5 | G3: 6 | H3: 7 | I3: 8 | J3: 9 | K3: 10 | L3: 11 | M3: 12
A4: A | B4: ='Sheet 1'!B4 -> 0.065 | C4: ='Sheet 1'!C4 -> 0.1 | D4: ='Sheet 1'!D4 -> 0.13 | E4: ='Sheet 1'!E4 -> 0.151 | F4: ='Sheet 1'!F4 -> 0.169 | G4: ='Sheet 1'!G4 -> 0.185 | H4: ='Sheet 1'!H4 -> 0.197 | I4: ='Sheet 1'!I4 -> 0.216 | ... M4: ='Sheet 1'!M4 -> 0.287 | N4: 660
A5: B | B5: ='Sheet 1'!B5 -> 0.066 | C5: ='Sheet 1'!C5 -> 0.114 | D5: ='Sheet 1'!D5 -> 0.136 | E5: ='Sheet 1'!E5 -> 0.158 | F5: ='Sheet 1'!F5 -> 0.169 | G5: ='Sheet 1'!G5 -> 0.191 | H5: ='Sheet 1'!H5 -> 0.207 | I5: ='Sheet 1'!I5 -> 0.22 | ... M5: ='Sheet 1'!M5 -> 0.286 | N5: 660
A6: C | B6: ='Sheet 1'!B6 -> 0.074 | C6: ='Sheet 1'!C6 -> 0.105 | D6: ='Sheet 1'!D6 -> 0.134 | E6: ='Sheet 1'!E6 -> 0.148 | F6: ='Sheet 1'!F6 -> 0.163 | G6: ='Sheet 1'!G6 -> 0.169 | H6: ='Sheet 1'!H6 -> 0.186 | I6: ='Sheet 1'!I6 -> 0.2 | ... M6: ='Sheet 1'!M6 -> 0.272 | N6: 660
A7: D | B7: ='Sheet 1'!B7 -> 0.077 | C7: ='Sheet 1'!C7 -> 0.101 | D7: ='Sheet 1'!D7 -> 0.131 | E7: ='Sheet 1'!E7 -> 0.142 | F7: ='Sheet 1'!F7 -> 0.156 | G7: ='Sheet 1'!G7 -> 0.169 | H7: ='Sheet 1'!H7 -> 0.183 | I7: ='Sheet 1'!I7 -> 0.205 | ... M7: ='Sheet 1'!M7 -> 0.264 | N7: 660
A8: E | B8: ='Sheet 1'!B8 -> 0.292 | C8: ='Sheet 1'!C8 -> 0.307 | D8: ='Sheet 1'!D8 -> 0.321 | E8: ='Sheet 1'!E8 -> 0.333 | F8: ='Sheet 1'!F8 -> 0.346 | G8: ='Sheet 1'!G8 -> 0.365 | H8: ='Sheet 1'!H8 -> 0.383 | I8: ='Sheet 1'!I8 -> 0.402 | ... M8: ='Sheet 1'!M8 -> 0.516 | N8: 660
A9: F | B9: ='Sheet 1'!B9 -> 0.291 | C9: ='Sheet 1'!C9 -> 0.316 | D9: ='Sheet 1'!D9 -> 0.321 | E9: ='Sheet 1'!E9 -> 0.336 | F9: ='Sheet 1'!F9 -> 0.35 | G9: ='Sheet 1'!G9 -> 0.361 | H9: ='Sheet 1'!H9 -> 0.381 | I9: ='Sheet 1'!I9 -> 0.389 | ... M9: ='Sheet 1'!M9 -> 0.511 | N9: 660
A10: G | B10: ='Sheet 1'!B10 -> 0.295 | C10: ='Sheet 1'!C10 -> 0.305 | D10: ='Sheet 1'!D10 -> 0.316 | E10: ='Sheet 1'!E10 -> 0.327 | F10: ='Sheet 1'!F10 -> 0.339 | G10: ='Sheet 1'!G10 -> 0.345 | H10: ='Sheet 1'!H10 -> 0.371 | I10: ='Sheet 1'!I10 -> 0.373 | ... M10: ='Sheet 1'!M10 -> 0.512 | N10: 660
A11: H | B11: ='Sheet 1'!B11 -> 0.279 | C11: ='Sheet 1'!C11 -> 0.284 | D11: ='Sheet 1'!D11 -> 0.307 | E11: ='Sheet 1'!E11 -> 0.32 | F11: ='Sheet 1'!F11 -> 0.341 | G11: ='Sheet 1'!G11 -> 0.346 | H11: ='Sheet 1'!H11 -> 0.368 | I11: ='Sheet 1'!I11 -> 0.375 | ... M11: ='Sheet 1'!M11 -> 0.492 | N11: 660
A16: Time (min) | B16: 17 | C16: =B16+17 -> 34 | D16: =C16+17 -> 51 | E16: =D16+17 -> 68 | F16: =E16+17 -> 85 | G16: =F16+17 -> 102 | H16: =G16+17 -> 119 | I16: =H16+17 -> 136 | J16: =I16+17 -> 153 | ... M16: =L16+17 -> 204
A17: Ch1 (A) | B17: =B4 -> 0.065 | C17: =C4 -> 0.1 | D17: =D4 -> 0.13 | E17: =E4 -> 0.151 | F17: =F4 -> 0.169 | G17: =G4 -> 0.185 | H17: =H4 -> 0.197 | I17: =I4 -> 0.216 | ... M17: =M4 -> 0.287
A18: Ch2 (B) | B18: =B5 -> 0.066 | C18: =C5 -> 0.114 | D18: =D5 -> 0.136 | E18: =E5 -> 0.158 | F18: =F5 -> 0.169 | G18: =G5 -> 0.191 | H18: =H5 -> 0.207 | I18: =I5 -> 0.22 | ... M18: =M5 -> 0.286
A19: Ch3 (C) | B19: =B6 -> 0.074 | C19: =C6 -> 0.105 | D19: =D6 -> 0.134 | E19: =E6 -> 0.148 | F19: =F6 -> 0.163 | G19: =G6 -> 0.169 | H19: =H6 -> 0.186 | I19: =I6 -> 0.2 | ... M19: =M6 -> 0.272
A20: Ch4 (D) | B20: =B7 -> 0.077 | C20: =C7 -> 0.101 | D20: =D7 -> 0.131 | E20: =E7 -> 0.142 | F20: =F7 -> 0.156 | G20: =G7 -> 0.169 | H20: =H7 -> 0.183 | I20: =I7 -> 0.205 | ... M20: =M7 -> 0.264
A22: Time (min) | B22: =17+M16 -> 221 | C22: =B22+17 -> 238 | D22: =C22+17 -> 255 | E22: =D22+17 -> 272 | F22: =E22+17 -> 289 | G22: =F22+17 -> 306 | H22: =G22+17 -> 323 | I22: =H22+17 -> 340 | J22: =I22+17 -> 357 | ... M22: =L22+17 -> 408
A23: Ch1 (E) | B23: 0.292 | C23: 0.307 | D23: 0.321 | E23: 0.333 | F23: 0.346 | G23: 0.365 | H23: 0.383 | I23: 0.402 | J23: 0.431 | K23: 0.459 | L23: 0.486 | M23: 0.516
A24: Ch2 (F) | B24: 0.291 | C24: 0.316 | D24: 0.321 | E24: 0.336 | F24: 0.35 | G24: 0.361 | H24: 0.381 | I24: 0.389 | J24: 0.41 | K24: 0.437 | L24: 0.459 | M24: 0.511
A25: Ch3 (G) | B25: 0.295 | C25: 0.305 | D25: 0.316 | E25: 0.327 | F25: 0.339 | G25: 0.345 | H25: 0.371 | I25: 0.373 | J25: 0.402 | K25: 0.422 | L25: 0.449 | M25: 0.512
A26: Ch4 (H) | B26: 0.279 | C26: 0.284 | D26: 0.307 | E26: 0.32 | F26: 0.341 | G26: 0.346 | H26: 0.368 | I26: 0.375 | J26: 0.381 | K26: 0.396 | L26: 0.433 | M26: 0.492
A29: Formulations
A30: Ch1 | B30: P23-1
A31: Ch2 | B31: P23-2
A32: Ch3 | B32: P23-3 | N32: =5*60 -> 300
A33: Ch4 | B33: P23-4
A36: Receptor cell (ml)
A37: Ch1 | B37: 19
A38: Ch2 | B38: 19.6
A39: Ch3 | B39: 17.4
A40: Ch4 | B40: 20.2
A43: Donor cell (ml)
A44: Ch1 | B44: 0.5 | C44: 250 | D44: ug MB
A45: Ch2 | B45: 0.5 | C45: 250 | D45: ug MB
A46: Ch3 | B46: 0.5 | C46: 250 | D46: ug MB
A47: Ch4 | B47: 0.5 | C47: 250 | D47: ug MB
A50: Flow RMSP (Q+) / (Q-) ml/min | C50: 7RPM
A51: Ch1
A52: Ch2
A53: Ch3
A54: Ch4
...

Sheet Correction Blank
A3: Correction O.D
B4: Time (min) | C4: =17 -> 17 | D4: =C4+17 -> 34 | E4: =D4+17 -> 51 | F4: =E4+17 -> 68 | G4: =F4+17 -> 85 | H4: =G4+17 -> 102 | I4: =H4+17 -> 119 | J4: =I4+17 -> 136 | K4: =J4+17 -> 153 | ... Z4: =Y4+17 -> 408
B5: =Info!B30 -> P23-1 | C5: =Info!B17-0.05 -> 0.015 | D5: =Info!C17-0.05 -> 0.05 | E5: =Info!D17-0.05 -> 0.08 | F5: =Info!E17-0.05 -> 0.101 | G5: =Info!F17-0.05 -> 0.119 | H5: =Info!G17-0.05 -> 0.135 | I5: =Info!H17-0.05 -> 0.147 | J5: =Info!I17-0.05 -> 0.166 | ... N5: =Info!M17-0.05 -> 0.237 | O5: =Info!B23-0.05 -> 0.242 | P5: =Info!C23-0.05 -> 0.257 | Q5: =Info!D23-0.05 -> 0.271 | R5: =Info!E23-0.05 -> 0.283 | S5: =Info!F23-0.05 -> 0.296 | T5: =Info!G23-0.05 -> 0.315 | U5: =Info!H23-0.05 -> 0.333 | V5: =Info!I23-0.05 -> 0.352 | ... Z5: =Info!M23-0.05 -> 0.466
B6: =Info!B31 -> P23-2 | C6: =Info!B18-0.05 -> 0.016 | D6: =Info!C18-0.05 -> 0.064 | E6: =Info!D18-0.05 -> 0.086 | F6: =Info!E18-0.05 -> 0.108 | G6: =Info!F18-0.05 -> 0.119 | H6: =Info!G18-0.05 -> 0.141 | I6: =Info!H18-0.05 -> 0.157 | J6: =Info!I18-0.05 -> 0.17 | ... N6: =Info!M18-0.05 -> 0.236 | O6: =Info!B24-0.05 -> 0.241 | P6: =Info!C24-0.05 -> 0.266 | Q6: =Info!D24-0.05 -> 0.271 | R6: =Info!E24-0.05 -> 0.286 | S6: =Info!F24-0.05 -> 0.3 | T6: =Info!G24-0.05 -> 0.311 | U6: =Info!H24-0.05 -> 0.331 | V6: =Info!I24-0.05 -> 0.339 | ... Z6: =Info!M24-0.05 -> 0.461
B7: =Info!B32 -> P23-3 | C7: =Info!B19-0.05 -> 0.024 | D7: =Info!C19-0.05 -> 0.055 | E7: =Info!D19-0.05 -> 0.084 | F7: =Info!E19-0.05 -> 0.098 | G7: =Info!F19-0.05 -> 0.113 | H7: =Info!G19-0.05 -> 0.119 | I7: =Info!H19-0.05 -> 0.136 | J7: =Info!I19-0.05 -> 0.15 | ... N7: =Info!M19-0.05 -> 0.222 | O7: =Info!B25-0.05 -> 0.245 | P7: =Info!C25-0.05 -> 0.255 | Q7: =Info!D25-0.05 -> 0.266 | R7: =Info!E25-0.05 -> 0.277 | S7: =Info!F25-0.05 -> 0.289 | T7: =Info!G25-0.05 -> 0.295 | U7: =Info!H25-0.05 -> 0.321 | V7: =Info!I25-0.05 -> 0.323 | ... Z7: =Info!M25-0.05 -> 0.462
B8: =Info!B33 -> P23-4 | C8: =Info!B20-0.05 -> 0.027 | D8: =Info!C20-0.05 -> 0.051 | E8: =Info!D20-0.05 -> 0.081 | F8: =Info!E20-0.05 -> 0.092 | G8: =Info!F20-0.05 -> 0.106 | H8: =Info!G20-0.05 -> 0.119 | I8: =Info!H20-0.05 -> 0.133 | J8: =Info!I20-0.05 -> 0.155 | ... N8: =Info!M20-0.05 -> 0.214 | O8: =Info!B26-0.05 -> 0.229 | P8: =Info!C26-0.05 -> 0.234 | Q8: =Info!D26-0.05 -> 0.257 | R8: =Info!E26-0.05 -> 0.27 | S8: =Info!F26-0.05 -> 0.291 | T8: =Info!G26-0.05 -> 0.296 | U8: =Info!H26-0.05 -> 0.318 | V8: =Info!I26-0.05 -> 0.325 | ... Z8: =Info!M26-0.05 -> 0.442

Sheet Conversions
C2: =0.25/20*100 -> 1.25
A3: Convert to MB content (ug)
B4: Time (min) | C4: =17 -> 17 | D4: =C4+17 -> 34 | E4: =D4+17 -> 51 | F4: =E4+17 -> 68 | G4: =F4+17 -> 85 | H4: =G4+17 -> 102 | I4: =H4+17 -> 119 | J4: =I4+17 -> 136 | K4: =J4+17 -> 153 | ... Z4: =Y4+17 -> 408
B5: =Info!B30 -> P23-1 | C5: =('Correction Blank'!C5-0.0796)/0.1195 -> -0.54058577 | D5: =('Correction Blank'!D5-0.0796)/0.1195 -> -0.24769874 | E5: =('Correction Blank'!E5-0.0796)/0.1195 -> 0.0033472803 | F5: =('Correction Blank'!F5-0.0796)/0.1195 -> 0.1790795 | G5: =('Correction Blank'!G5-0.0796)/0.1195 -> 0.32970711 | H5: =('Correction Blank'!H5-0.0796)/0.1195 -> 0.46359833 | I5: =('Correction Blank'!I5-0.0796)/0.1195 -> 0.56401674 | J5: =('Correction Blank'!J5-0.0796)/0.1195 -> 0.72301255 | ... Z5: =('Correction Blank'!Z5-0.0796)/0.1195 -> 3.2334728
B6: =Info!B31 -> P23-2 | C6: =('Correction Blank'!C6-0.0796)/0.1195 -> -0.53221757 | D6: =('Correction Blank'!D6-0.0796)/0.1195 -> -0.13054393 | E6: =('Correction Blank'!E6-0.0796)/0.1195 -> 0.053556485 | F6: =('Correction Blank'!F6-0.0796)/0.1195 -> 0.2376569 | G6: =('Correction Blank'!G6-0.0796)/0.1195 -> 0.32970711 | H6: =('Correction Blank'!H6-0.0796)/0.1195 -> 0.51380753 | I6: =('Correction Blank'!I6-0.0796)/0.1195 -> 0.64769874 | J6: =('Correction Blank'!J6-0.0796)/0.1195 -> 0.75648536 | ... Z6: =('Correction Blank'!Z6-0.0796)/0.1195 -> 3.1916318
B7: =Info!B32 -> P23-3 | C7: =('Correction Blank'!C7-0.0796)/0.1195 -> -0.46527197 | D7: =('Correction Blank'!D7-0.0796)/0.1195 -> -0.20585774 | E7: =('Correction Blank'!E7-0.0796)/0.1195 -> 0.036820084 | F7: =('Correction Blank'!F7-0.0796)/0.1195 -> 0.1539749 | G7: =('Correction Blank'!G7-0.0796)/0.1195 -> 0.27949791 | H7: =('Correction Blank'!H7-0.0796)/0.1195 -> 0.32970711 | I7: =('Correction Blank'!I7-0.0796)/0.1195 -> 0.47196653 | J7: =('Correction Blank'!J7-0.0796)/0.1195 -> 0.58912134 | ... Z7: =('Correction Blank'!Z7-0.0796)/0.1195 -> 3.2
B8: =Info!B33 -> P23-4 | C8: =('Correction Blank'!C8-0.0796)/0.1195 -> -0.44016736 | D8: =('Correction Blank'!D8-0.0796)/0.1195 -> -0.23933054 | E8: =('Correction Blank'!E8-0.0796)/0.1195 -> 0.011715481 | F8: =('Correction Blank'!F8-0.0796)/0.1195 -> 0.10376569 | G8: =('Correction Blank'!G8-0.0796)/0.1195 -> 0.2209205 | H8: =('Correction Blank'!H8-0.0796)/0.1195 -> 0.32970711 | I8: =('Correction Blank'!I8-0.0796)/0.1195 -> 0.44686192 | J8: =('Correction Blank'!J8-0.0796)/0.1195 -> 0.63096234 | ... Z8: =('Correction Blank'!Z8-0.0796)/0.1195 -> 3.032636
A12: a | B12: 0.1195
A13: b | B13: 0.0796
A14: Vol.Media (ml) | B14: 20
I38: =357/60 -> 5.95

Sheet Cumulative Release
A1: HTDPA P15 – Sampling-Corrected Cumulative Methylene Blue Release
A2: P23(Poloxamer 407), 1 µm PET membrane,7 RPM, 28 °C, n=4 channels
A3: EDIT
A4: Calculation inputs
A5: Receptor volume (mL) | B5: =Info!B37 -> 19 | C5: =Info!C37 -> 0 | D5: Equation | E5: Qn = V·Cn + Vs·SUM(C1:Cn-1)
B6: 19.6
B7: 17.4
B8: 20.2
A10: Sample volume replaced (mL) | B10: 0.25 | D10: Interpretation | E10: Current amount in the 20 mL receptor + all MB removed in previous 250 µL samples. The current sample is not added separately.
A11: Initial MB in donor (µg) | B11: 250 | D11: Data handling | E11: Concentrations are linked directly from Conversions and are not truncated; negative early values are retained exactly as calculated.
A13: Measured concentration (µg/mL)
B14: Time (min) | C14: =Conversions!C4 -> 17 | D14: =Conversions!D4 -> 34 | E14: =Conversions!E4 -> 51 | F14: =Conversions!F4 -> 68 | G14: =Conversions!G4 -> 85 | H14: =Conversions!H4 -> 102 | I14: =Conversions!I4 -> 119 | J14: =Conversions!J4 -> 136 | ... Z14: =Conversions!Z4 -> 408
B15: =Conversions!B5 -> P23-1 | C15: =Conversions!C5 -> -0.54058577 | D15: =Conversions!D5 -> -0.24769874 | E15: =Conversions!E5 -> 0.0033472803 | F15: =Conversions!F5 -> 0.1790795 | G15: =Conversions!G5 -> 0.32970711 | H15: =Conversions!H5 -> 0.46359833 | I15: =Conversions!I5 -> 0.56401674 | ... Z15: =Conversions!Z5 -> 3.2334728
B16: =Conversions!B6 -> P23-2 | C16: =Conversions!C6 -> -0.53221757 | D16: =Conversions!D6 -> -0.13054393 | E16: =Conversions!E6 -> 0.053556485 | F16: =Conversions!F6 -> 0.2376569 | G16: =Conversions!G6 -> 0.32970711 | H16: =Conversions!H6 -> 0.51380753 | I16: =Conversions!I6 -> 0.64769874 | ... Z16: =Conversions!Z6 -> 3.1916318
B17: =Conversions!B7 -> P23-3 | C17: =Conversions!C7 -> -0.46527197 | D17: =Conversions!D7 -> -0.20585774 | E17: =Conversions!E7 -> 0.036820084 | F17: =Conversions!F7 -> 0.1539749 | G17: =Conversions!G7 -> 0.27949791 | H17: =Conversions!H7 -> 0.32970711 | I17: =Conversions!I7 -> 0.47196653 | ... Z17: =Conversions!Z7 -> 3.2
B18: =Conversions!B8 -> P23-4 | C18: =Conversions!C8 -> -0.44016736 | D18: =Conversions!D8 -> -0.23933054 | E18: =Conversions!E8 -> 0.011715481 | F18: =Conversions!F8 -> 0.10376569 | G18: =Conversions!G8 -> 0.2209205 | H18: =Conversions!H8 -> 0.32970711 | I18: =Conversions!I8 -> 0.44686192 | ... Z18: =Conversions!Z8 -> 3.032636
A20: Sampling-corrected cumulative release (µg)
B21: Time (min) | C21: =C14 -> 17 | D21: =D14 -> 34 | E21: =E14 -> 51 | F21: =F14 -> 68 | G21: =G14 -> 85 | H21: =H14 -> 102 | I21: =I14 -> 119 | J21: =J14 -> 136 | ... Z21: =Z14 -> 408
B22: =B15 -> P23-1 | C22: =C15*$B$5 -> -10.27113 | D22: =D15*$B$5+$B$10*SUM($C15:C15) -> -4.8414226 | E22: =E15*$B$5+$B$10*SUM($C15:D15) -> -0.1334728 | F22: =F15*$B$5+$B$10*SUM($C15:E15) -> 3.2062762 | G22: =G15*$B$5+$B$10*SUM($C15:F15) -> 6.1129707 | H22: =H15*$B$5+$B$10*SUM($C15:G15) -> 8.7393305 | I22: =I15*$B$5+$B$10*SUM($C15:H15) -> 10.76318 | J22: =J15*$B$5+$B$10*SUM($C15:I15) -> 13.925105 | K22: =K15*$B$5+$B$10*SUM($C15:J15) -> 16.649791 | ... Z22: =Z15*$B$5+$B$10*SUM($C15:Y15) -> 68.557741
B23: =B16 -> P23-2 | C23: =C16*$B$6 -> -10.431464 | D23: =D16*$B$6+$B$10*SUM($C16:C16) -> -2.6917155 | E23: =E16*$B$6+$B$10*SUM($C16:D16) -> 0.88401674 | F23: =F16*$B$6+$B$10*SUM($C16:E16) -> 4.5057741 | G23: =G16*$B$6+$B$10*SUM($C16:F16) -> 6.3693724 | H23: =H16*$B$6+$B$10*SUM($C16:G16) -> 10.060167 | I23: =I16*$B$6+$B$10*SUM($C16:H16) -> 12.812887 | J23: =J16*$B$6+$B$10*SUM($C16:I16) -> 15.107029 | K23: =K16*$B$6+$B$10*SUM($C16:J16) -> 17.756402 | ... Z23: =Z16*$B$6+$B$10*SUM($C16:Y16) -> 69.604519
B24: =B17 -> P23-3 | C24: =C17*$B$7 -> -8.0957322 | D24: =D17*$B$7+$B$10*SUM($C17:C17) -> -3.6982427 | E24: =E17*$B$7+$B$10*SUM($C17:D17) -> 0.47288703 | F24: =F17*$B$7+$B$10*SUM($C17:E17) -> 2.5205858 | G24: =G17*$B$7+$B$10*SUM($C17:F17) -> 4.7431799 | H24: =H17*$B$7+$B$10*SUM($C17:G17) -> 5.6866946 | I24: =I17*$B$7+$B$10*SUM($C17:H17) -> 8.2444351 | J24: =J17*$B$7+$B$10*SUM($C17:I17) -> 10.400921 | K24: =K17*$B$7+$B$10*SUM($C17:J17) -> 13.169121 | ... Z24: =Z17*$B$7+$B$10*SUM($C17:Y17) -> 62.228536
B25: =B18 -> P23-4 | C25: =C18*$B$8 -> -8.8913808 | D25: =D18*$B$8+$B$10*SUM($C18:C18) -> -4.9445188 | E25: =E18*$B$8+$B$10*SUM($C18:D18) -> 0.066778243 | F25: =F18*$B$8+$B$10*SUM($C18:E18) -> 1.9291213 | G25: =G18*$B$8+$B$10*SUM($C18:F18) -> 4.32159 | H25: =H18*$B$8+$B$10*SUM($C18:G18) -> 6.5743096 | I25: =I18*$B$8+$B$10*SUM($C18:H18) -> 9.0232636 | J25: =J18*$B$8+$B$10*SUM($C18:I18) -> 12.853808 | K25: =K18*$B$8+$B$10*SUM($C18:J18) -> 16.054226 | ... Z25: =Z18*$B$8+$B$10*SUM($C18:Y18) -> 67.52954
A27: Sampling-corrected cumulative release (% of 250 µg donor dose)
B28: Time (min) | C28: =C14 -> 17 | D28: =D14 -> 34 | E28: =E14 -> 51 | F28: =F14 -> 68 | G28: =G14 -> 85 | H28: =H14 -> 102 | I28: =I14 -> 119 | J28: =J14 -> 136 | ... Z28: =Z14 -> 408
B29: =B22 -> P23-1 | C29: =C22/$B$11*100 -> -4.1084519 | D29: =D22/$B$11*100 -> -1.936569 | E29: =E22/$B$11*100 -> -0.053389121 | F29: =F22/$B$11*100 -> 1.2825105 | G29: =G22/$B$11*100 -> 2.4451883 | H29: =H22/$B$11*100 -> 3.4957322 | I29: =I22/$B$11*100 -> 4.305272 | J29: =J22/$B$11*100 -> 5.5700418 | ... Z29: =Z22/$B$11*100 -> 27.423096
B30: =B23 -> P23-2 | C30: =C23/$B$11*100 -> -4.1725858 | D30: =D23/$B$11*100 -> -1.0766862 | E30: =E23/$B$11*100 -> 0.35360669 | F30: =F23/$B$11*100 -> 1.8023096 | G30: =G23/$B$11*100 -> 2.547749 | H30: =H23/$B$11*100 -> 4.0240669 | I30: =I23/$B$11*100 -> 5.1251548 | J30: =J23/$B$11*100 -> 6.0428117 | ... Z30: =Z23/$B$11*100 -> 27.841808
B31: =B24 -> P23-3 | C31: =C24/$B$11*100 -> -3.2382929 | D31: =D24/$B$11*100 -> -1.4792971 | E31: =E24/$B$11*100 -> 0.18915481 | F31: =F24/$B$11*100 -> 1.0082343 | G31: =G24/$B$11*100 -> 1.897272 | H31: =H24/$B$11*100 -> 2.2746778 | I31: =I24/$B$11*100 -> 3.2977741 | J31: =J24/$B$11*100 -> 4.1603682 | ... Z31: =Z24/$B$11*100 -> 24.891414
B32: =B25 -> P23-4 | C32: =C25/$B$11*100 -> -3.5565523 | D32: =D25/$B$11*100 -> -1.9778075 | E32: =E25/$B$11*100 -> 0.026711297 | F32: =F25/$B$11*100 -> 0.77164854 | G32: =G25/$B$11*100 -> 1.728636 | H32: =H25/$B$11*100 -> 2.6297238 | I32: =I25/$B$11*100 -> 3.6093054 | J32: =J25/$B$11*100 -> 5.141523 | ... Z32: =Z25/$B$11*100 -> 27.011816
A34: All CH | B34: Average (%) | C34: =AVERAGE(C29:C32) -> -3.7689707 | D34: =AVERAGE(D29:D32) -> -1.61759 | E34: =AVERAGE(E29:E32) -> 0.12902092 | F34: =AVERAGE(F29:F32) -> 1.2161757 | G34: =AVERAGE(G29:G32) -> 2.1547113 | H34: =AVERAGE(H29:H32) -> 3.1060502 | I34: =AVERAGE(I29:I32) -> 4.0843766 | J34: =AVERAGE(J29:J32) -> 5.2286862 | ... Z34: =AVERAGE(Z29:Z32) -> 26.792033
B35: S.D. (%) | C35: =STDEV(C29:C32) -> 0.44903345 | D35: =STDEV(D29:D32) -> 0.4255217 | E35: =STDEV(E29:E32) -> 0.18055058 | F35: =STDEV(F29:F32) -> 0.44301892 | G35: =STDEV(G29:G32) -> 0.40276985 | H35: =STDEV(H29:H32) -> 0.79847222 | I35: =STDEV(I29:I32) -> 0.81167527 | J35: =STDEV(J29:J32) -> 0.80171167 | ... Z35: =STDEV(Z29:Z32) -> 1.3116051
B36: C.V. (%) | C36: =IFERROR(C35/C34*100,"") -> -11.913954 | D36: =IFERROR(D35/D34*100,"") -> -26.305907 | E36: =IFERROR(E35/E34*100,"") -> 139.939 | F36: =IFERROR(F35/F34*100,"") -> 36.427213 | G36: =IFERROR(G35/G34*100,"") -> 18.692521 | H36: =IFERROR(H35/H34*100,"") -> 25.706996 | I36: =IFERROR(I35/I34*100,"") -> 19.872684 | J36: =IFERROR(J35/J34*100,"") -> 15.332947 | ... Z36: =IFERROR(Z35/Z34*100,"") -> 4.895504
A38: Note | B38: The existing Conversions sheet applies sampling correction only at selected cells. This sheet uses the cumulative correction at every time point and leaves the original sheet unchanged.
